<?xml version='1.0'?>
<robot name="my_first_robot">

  <!-- Base Footprint -->
  <link name = "base_footprint"/>

  <!-- Base Link -->
  <link name="base_link">
    <visual>
      <!--origin xyz="0 0 0" rpy="0 0 0" /-->
      <geometry>
          <box size="0.5 0.5 0.25"/>
      </geometry>
    </visual>
  </link>

  <!-- Joint between Base footprint and base_link --> 
  <joint name="base_joint" type="fixed">
    <parent link="base_footprint"/>
    <child link="base_link" />
    <origin xyz="0 0 0.010" rpy="0 0 0"/>
  </joint>

  <!-- Right Wheel -->
  <link name="right_wheel">
    <visual>
      <origin xyz="0 0 0" rpy="1.570795 0 0" />
      <geometry>
          <cylinder length="0.1" radius="0.2" />
      </geometry>
    </visual>
  </link>
  <!-- Joint between base_link and right wheel --> 
  <joint name="joint_right_wheel" type="continuous">
    <parent link="base_link"/>
    <child link="right_wheel"/>
    <origin xyz="0 -0.30 0" rpy="0 0 0" /> 
    <axis xyz="0 1 0" rpy="0 0 0"/>
  </joint>

  <!-- Left Wheel -->
  <link name="left_wheel">
    <visual>
      <origin xyz="0 0 0" rpy="1.570795 0 0" />
      <geometry>
          <cylinder length="0.1" radius="0.2" />
      </geometry>
    </visual>
  </link>
  <!-- Joint between base_link and left wheel --> 
  <joint name="joint_left_wheel" type="continuous">
    <parent link="base_link"/>
    <child link="left_wheel"/>
    <origin xyz="0 0.30 0" rpy="0 0 0" /> 
    <axis xyz="0 1 0" />
  </joint>

</robot>
